---
title: JavaScript 异步编程
date: 2022-03-18 00:55:10
permalink: /pages/195534/
categories:
  - 前端
  - Vue2
tags:
  - 
---
# JavaScript 异步编程



### 定时器

```javascript
console.log(1)

setTimeout() => {
    console.log(2)
}

console.log(3)

// 输出结果是 1 3 2  
// 往下执行时 不会等待setTimeout定时器的结束 而是直接向下继续执行
```



### ajax请求

```js
//无论是使用原生的 XMLHttpRequest 还是 Jquery 的ajax 还是是 axios 都是异步的

$.ajax({
    method:'',
    url:'',
    success: function(data) {
        // data 就是响应结果
    }
})

// 异步代码 往往都伴随一个回调函数来接受结果  回头调用
axios({
    methos:'',
    url:''
}).then(res => {
    
})
```

## 1. callback 回调函数
有时候,我们需要在异步操作的结果中执行另外一个异步操作

```js
axios({
    methos:'',
    url:''
}).then(res => {
    axios({
    methos:'',
    url:''
		}).then(res => {
 
			})
})

```

当出现类型上面的嵌套异步时,非常不便于阅读和理解



## 2. Promise

```js
new Promist((resovle,reject) => {
    setTimeout(() => {
        resolve()  // 在Promise中 成功resolve 失败 reject
    },1000)
})
```



## 3.Generator 生成器函数(淘汰了)

## 4. Async 函数 (推荐)

有了 Async 函数,可以极大了简化我们的异步操作,前提是你的异步操作支持Promise

如axios支持Promiose,所以我们可以使用async函数调用优化它, 任何异步如果支持promise则都可以使用Async函数来使用

```js
axios({
    methos:'',
    url:''
}).then(res => {
    
})

// async 只能用于函数 只要是函数都可以被标记为async,无论这个函数是什么形式
async function main () {
    // 通过 async-await 我们可以像屑同步一样来写异步代码 
    						// 使用await关键字的父函数必须加async
    const res =await axios({  //await等待,只有 await 后面的操作结束了,代码才会继续往后执行
         methos:'',
   		 url:''
    })
    
    console.log(res)
    
    
     const res2 =await axios({  //res2不会马上执行 要等 res 请求结束后才会执行
         methos:'',
   		 url:''
    })
     
     console.log(res2)
}
```



### Async 的 返回值

```js
async function main() {
    return 123
    //相对应 async 不会把不是promise对象的返回值返回
    //return new Promise(resolve => {
    //resolve(123)
//})
}

const data = main()
console.log(data)   //返回为一个 Promise对象
// async 始终返回一个Promise对象 如果这个返回值不是Promise对象则封装成Promise对象

//第一种方式获取值 用then获取
mian().then(data => {
    console.log(data)  //promise对象用then返回结果
})

//第二种方式获取值  用await获取
async function main2(){
    const data = await mian()
    console.log(data)
}

main2()

```



## async 函数的错误处理

使用catch捕获异常

```js
async function main() {
    JSON.parse('123124')
    return 123
}

main().then(res => {
    console.log(123)
}).catch(err => {
    console.log('发生异常',errw)
})
```

推荐使用 try-catch 捕获

```js
async function main2() {
    try{
        // 如果try 里面的代码遇到异常,则停止执行try里面下面的代码,进入catch
        const data =await main()
        console.log(data)
    } catch (err) {
        console.log('异常')
    }
}
```

